<?xml version="1.0" encoding="utf-8"?>
<!-- This URDF was automatically created by SolidWorks to URDF Exporter! Originally created by Stephen Brawner (brawner@gmail.com) 
     Commit Version: 1.6.0-4-g7f85cfe  Build Version: 1.6.7995.38578
     For more information, please see http://wiki.ros.org/sw_urdf_exporter -->
<robot
  name="urdf2">
  <link
    name="eslabon_0">
    <inertial>
      <origin
        xyz="1.0422E-11 0.017244 0.037691"
        rpy="0 0 0" />
      <mass
        value="0.89153" />
      <inertia
        ixx="0.0016943"
        ixy="7.8702E-15"
        ixz="-6.1537E-14"
        iyy="0.0017073"
        iyz="-0.00010181"
        izz="0.0019831" />
    </inertial>
    <visual>
      <origin
        xyz="0 0 0"
        rpy="0 0 0" />
      <geometry>
        <mesh
          filename="package://urdf2/meshes/eslabon_0.STL" />
      </geometry>
      <material
        name="">
        <color
          rgba="0.79216 0.81961 0.93333 1" />
      </material>
    </visual>
    <collision>
      <origin
        xyz="0 0 0"
        rpy="0 0 0" />
      <geometry>
        <mesh
          filename="package://urdf2/meshes/eslabon_0.STL" />
      </geometry>
    </collision>
  </link>
  <link
    name="Link_1">
    <inertial>
      <origin
        xyz="4.85722573273506E-16 4.9960036108132E-16 -0.0203423923814379"
        rpy="0 0 0" />
      <mass
        value="0.235997319223989" />
      <inertia
        ixx="0.000242917324320263"
        ixy="-2.03287907341032E-20"
        ixz="-4.98707991001971E-20"
        iyy="0.000301154082942842"
        iyz="-2.13013066383385E-20"
        izz="0.000218774157929577" />
    </inertial>
    <visual>
      <origin
        xyz="0 0 0"
        rpy="0 0 0" />
      <geometry>
        <mesh
          filename="package://urdf2/meshes/Link_1.STL" />
      </geometry>
      <material
        name="">
        <color
          rgba="0.792156862745098 0.819607843137255 0.933333333333333 1" />
      </material>
    </visual>
    <collision>
      <origin
        xyz="0 0 0"
        rpy="0 0 0" />
      <geometry>
        <mesh
          filename="package://urdf2/meshes/Link_1.STL" />
      </geometry>
    </collision>
  </link>
  <joint
    name="Joint_1"
    type="revolute">
    <origin
      xyz="0 0 0.145"
      rpy="0 0 -1.2171" />
    <parent
      link="eslabon_0" />
    <child
      link="Link_1" />
    <axis
      xyz="0 0 1" />
    <limit
      lower="0"
      upper="3.142"
      effort="300"
      velocity="3" />
  </joint>
  <link
    name="link_2">
    <inertial>
      <origin
        xyz="0.0233269033944592 2.4980018054066E-15 0.0586342311289204"
        rpy="0 0 0" />
      <mass
        value="0.35706117343289" />
      <inertia
        ixx="0.00142940937450205"
        ixy="-1.0842021724855E-19"
        ixz="-0.000540372449573386"
        iyy="0.00155564200618658"
        iyz="-1.89735380184963E-19"
        izz="0.000544753645972744" />
    </inertial>
    <visual>
      <origin
        xyz="0 0 0"
        rpy="0 0 0" />
      <geometry>
        <mesh
          filename="package://urdf2/meshes/link_2.STL" />
      </geometry>
      <material
        name="">
        <color
          rgba="0.792156862745098 0.819607843137255 0.933333333333333 1" />
      </material>
    </visual>
    <collision>
      <origin
        xyz="0 0 0"
        rpy="0 0 0" />
      <geometry>
        <mesh
          filename="package://urdf2/meshes/link_2.STL" />
      </geometry>
    </collision>
  </link>
  <joint
    name="Joint_2"
    type="continuous">
    <origin
      xyz="0 0 0"
      rpy="0 0 0" />
    <parent
      link="Link_1" />
    <child
      link="link_2" />
    <axis
      xyz="0 1 0" />
    <limit
      lower="-1.57"
      upper="1.57"
      effort="200"
      velocity="3" />
  </joint>
  <link
    name="link_3">
    <inertial>
      <origin
        xyz="-0.0135763809770153 -0.0555832299864361 -6.97451801867643E-09"
        rpy="0 0 0" />
      <mass
        value="0.197506281990069" />
      <inertia
        ixx="0.000202701886888169"
        ixy="-2.93205804778591E-05"
        ixz="2.71305654108263E-11"
        iyy="8.9821788904807E-05"
        iyz="1.57443366058806E-11"
        izz="0.000191906644680011" />
    </inertial>
    <visual>
      <origin
        xyz="0 0 0"
        rpy="0 0 0" />
      <geometry>
        <mesh
          filename="package://urdf2/meshes/link_3.STL" />
      </geometry>
      <material
        name="">
        <color
          rgba="0.792156862745098 0.819607843137255 0.933333333333333 1" />
      </material>
    </visual>
    <collision>
      <origin
        xyz="0 0 0"
        rpy="0 0 0" />
      <geometry>
        <mesh
          filename="package://urdf2/meshes/link_3.STL" />
      </geometry>
    </collision>
  </link>
  <joint
    name="Joint_3"
    type="revolute">
    <origin
      xyz="0.06605 0 0.13468"
      rpy="1.5708 -1.1148 0" />
    <parent
      link="link_2" />
    <child
      link="link_3" />
    <axis
      xyz="0 0 -1" />
    <limit
      lower="0"
      upper="3.142"
      effort="200"
      velocity="3" />
  </joint>
  <link
    name="link_4">
    <inertial>
      <origin
        xyz="0.0252610623340964 -1.57198752792631E-07 1.05072867018219E-07"
        rpy="0 0 0" />
      <mass
        value="0.0567373643332565" />
      <inertia
        ixx="1.2172811083238E-05"
        ixy="-5.09895555882774E-11"
        ixz="1.15162084022227E-10"
        iyy="1.52409575169798E-05"
        iyz="-1.92566419846967E-10"
        izz="1.6776681364006E-05" />
    </inertial>
    <visual>
      <origin
        xyz="0 0 0"
        rpy="0 0 0" />
      <geometry>
        <mesh
          filename="package://urdf2/meshes/link_4.STL" />
      </geometry>
      <material
        name="">
        <color
          rgba="0.792156862745098 0.819607843137255 0.933333333333333 1" />
      </material>
    </visual>
    <collision>
      <origin
        xyz="0 0 0"
        rpy="0 0 0" />
      <geometry>
        <mesh
          filename="package://urdf2/meshes/link_4.STL" />
      </geometry>
    </collision>
  </link>
  <joint
    name="Joint_4"
    type="continuous">
    <origin
      xyz="-0.02966 -0.12143 0"
      rpy="0 0 -1.005" />
    <parent
      link="link_3" />
    <child
      link="link_4" />
    <axis
      xyz="0 0 -1" />
    <limit
      upper="-3.142"
      effort="200"
      velocity="3" />
  </joint>
</robot>